[2025-10-27T13:38:25.808+0000] {local_task_job_runner.py:120} INFO - ::group::Pre task execution logs
[2025-10-27T13:38:25.826+0000] {taskinstance.py:2076} INFO - Dependencies all met for dep_context=non-requeueable deps ti=<TaskInstance: test_mysql_connection.test_mysql_connection manual__2025-10-27T13:38:22.282724+00:00 [queued]>
[2025-10-27T13:38:25.831+0000] {taskinstance.py:2076} INFO - Dependencies all met for dep_context=requeueable deps ti=<TaskInstance: test_mysql_connection.test_mysql_connection manual__2025-10-27T13:38:22.282724+00:00 [queued]>
[2025-10-27T13:38:25.832+0000] {taskinstance.py:2306} INFO - Starting attempt 1 of 2
[2025-10-27T13:38:25.843+0000] {taskinstance.py:2330} INFO - Executing <Task(PythonOperator): test_mysql_connection> on 2025-10-27 13:38:22.282724+00:00
[2025-10-27T13:38:25.849+0000] {warnings.py:112} WARNING - /home/***/.local/lib/python3.12/site-packages/***/task/task_runner/standard_task_runner.py:62: DeprecationWarning: This process (pid=186) is multi-threaded, use of fork() may lead to deadlocks in the child.
  pid = os.fork()

[2025-10-27T13:38:25.851+0000] {standard_task_runner.py:64} INFO - Started process 188 to run task
[2025-10-27T13:38:25.851+0000] {standard_task_runner.py:90} INFO - Running: ['***', 'tasks', 'run', 'test_mysql_connection', 'test_mysql_connection', 'manual__2025-10-27T13:38:22.282724+00:00', '--job-id', '5', '--raw', '--subdir', 'DAGS_FOLDER/tes.py', '--cfg-path', '/tmp/tmpzz5nsoiw']
[2025-10-27T13:38:25.853+0000] {standard_task_runner.py:91} INFO - Job 5: Subtask test_mysql_connection
[2025-10-27T13:38:25.887+0000] {task_command.py:426} INFO - Running <TaskInstance: test_mysql_connection.test_mysql_connection manual__2025-10-27T13:38:22.282724+00:00 [running]> on host a0076f556b70
[2025-10-27T13:38:25.974+0000] {taskinstance.py:2648} INFO - Exporting env vars: AIRFLOW_CTX_DAG_OWNER='***' AIRFLOW_CTX_DAG_ID='test_mysql_connection' AIRFLOW_CTX_TASK_ID='test_mysql_connection' AIRFLOW_CTX_EXECUTION_DATE='2025-10-27T13:38:22.282724+00:00' AIRFLOW_CTX_TRY_NUMBER='1' AIRFLOW_CTX_DAG_RUN_ID='manual__2025-10-27T13:38:22.282724+00:00'
[2025-10-27T13:38:25.976+0000] {taskinstance.py:430} INFO - ::endgroup::
[2025-10-27T13:38:25.984+0000] {logging_mixin.py:188} INFO - MySQL Connection Test Failed!
[2025-10-27T13:38:25.985+0000] {logging_mixin.py:188} INFO - Error: The conn_id `mysql_default` isn't defined
[2025-10-27T13:38:25.985+0000] {taskinstance.py:441} INFO - ::group::Post task execution logs
[2025-10-27T13:38:25.993+0000] {taskinstance.py:2905} ERROR - Task failed with exception
Traceback (most recent call last):
  File "/home/airflow/.local/lib/python3.12/site-packages/airflow/models/taskinstance.py", line 465, in _execute_task
    result = _execute_callable(context=context, **execute_callable_kwargs)
             ^^^^^^^^^^^^^^^^^^^^^^^^^^^^^^^^^^^^^^^^^^^^^^^^^^^^^^^^^^^^^
  File "/home/airflow/.local/lib/python3.12/site-packages/airflow/models/taskinstance.py", line 432, in _execute_callable
    return execute_callable(context=context, **execute_callable_kwargs)
           ^^^^^^^^^^^^^^^^^^^^^^^^^^^^^^^^^^^^^^^^^^^^^^^^^^^^^^^^^^^^
  File "/home/airflow/.local/lib/python3.12/site-packages/airflow/models/baseoperator.py", line 401, in wrapper
    return func(self, *args, **kwargs)
           ^^^^^^^^^^^^^^^^^^^^^^^^^^^
  File "/home/airflow/.local/lib/python3.12/site-packages/airflow/operators/python.py", line 235, in execute
    return_value = self.execute_callable()
                   ^^^^^^^^^^^^^^^^^^^^^^^
  File "/home/airflow/.local/lib/python3.12/site-packages/airflow/operators/python.py", line 252, in execute_callable
    return self.python_callable(*self.op_args, **self.op_kwargs)
           ^^^^^^^^^^^^^^^^^^^^^^^^^^^^^^^^^^^^^^^^^^^^^^^^^^^^^
  File "/opt/airflow/dags/tes.py", line 28, in test_mysql_connection
    raise e
  File "/opt/airflow/dags/tes.py", line 13, in test_mysql_connection
    connection = mysql_hook.get_conn()
                 ^^^^^^^^^^^^^^^^^^^^^
  File "/home/airflow/.local/lib/python3.12/site-packages/airflow/providers/mysql/hooks/mysql.py", line 188, in get_conn
    conn = self.connection or self.get_connection(getattr(self, self.conn_name_attr))
                              ^^^^^^^^^^^^^^^^^^^^^^^^^^^^^^^^^^^^^^^^^^^^^^^^^^^^^^^
  File "/home/airflow/.local/lib/python3.12/site-packages/airflow/hooks/base.py", line 83, in get_connection
    conn = Connection.get_connection_from_secrets(conn_id)
           ^^^^^^^^^^^^^^^^^^^^^^^^^^^^^^^^^^^^^^^^^^^^^^^
  File "/home/airflow/.local/lib/python3.12/site-packages/airflow/models/connection.py", line 519, in get_connection_from_secrets
    raise AirflowNotFoundException(f"The conn_id `{conn_id}` isn't defined")
airflow.exceptions.AirflowNotFoundException: The conn_id `mysql_default` isn't defined
[2025-10-27T13:38:25.999+0000] {taskinstance.py:1206} INFO - Marking task as UP_FOR_RETRY. dag_id=test_mysql_connection, task_id=test_mysql_connection, run_id=manual__2025-10-27T13:38:22.282724+00:00, execution_date=20251027T133822, start_date=20251027T133825, end_date=20251027T133825
[2025-10-27T13:38:26.013+0000] {standard_task_runner.py:110} ERROR - Failed to execute job 5 for task test_mysql_connection (The conn_id `mysql_default` isn't defined; 188)
[2025-10-27T13:38:26.031+0000] {local_task_job_runner.py:243} INFO - Task exited with return code 1
[2025-10-27T13:38:26.047+0000] {taskinstance.py:3503} INFO - 0 downstream tasks scheduled from follow-on schedule check
[2025-10-27T13:38:26.049+0000] {local_task_job_runner.py:222} INFO - ::endgroup::
