[2025-10-27T15:04:02.770+0000] {local_task_job_runner.py:120} INFO - ::group::Pre task execution logs
[2025-10-27T15:04:02.787+0000] {taskinstance.py:2076} INFO - Dependencies all met for dep_context=non-requeueable deps ti=<TaskInstance: mysql_to_postgres_etl.load_to_postgres manual__2025-10-27T15:03:52.290525+00:00 [queued]>
[2025-10-27T15:04:02.792+0000] {taskinstance.py:2076} INFO - Dependencies all met for dep_context=requeueable deps ti=<TaskInstance: mysql_to_postgres_etl.load_to_postgres manual__2025-10-27T15:03:52.290525+00:00 [queued]>
[2025-10-27T15:04:02.793+0000] {taskinstance.py:2306} INFO - Starting attempt 1 of 2
[2025-10-27T15:04:02.802+0000] {taskinstance.py:2330} INFO - Executing <Task(PythonOperator): load_to_postgres> on 2025-10-27 15:03:52.290525+00:00
[2025-10-27T15:04:02.808+0000] {warnings.py:112} WARNING - /home/***/.local/lib/python3.12/site-packages/***/task/task_runner/standard_task_runner.py:62: DeprecationWarning: This process (pid=744) is multi-threaded, use of fork() may lead to deadlocks in the child.
  pid = os.fork()

[2025-10-27T15:04:02.809+0000] {standard_task_runner.py:64} INFO - Started process 746 to run task
[2025-10-27T15:04:02.809+0000] {standard_task_runner.py:90} INFO - Running: ['***', 'tasks', 'run', 'mysql_to_postgres_etl', 'load_to_postgres', 'manual__2025-10-27T15:03:52.290525+00:00', '--job-id', '43', '--raw', '--subdir', 'DAGS_FOLDER/mysql_to_postgres_etl.py', '--cfg-path', '/tmp/tmpgo5yohkm']
[2025-10-27T15:04:02.810+0000] {standard_task_runner.py:91} INFO - Job 43: Subtask load_to_postgres
[2025-10-27T15:04:02.871+0000] {task_command.py:426} INFO - Running <TaskInstance: mysql_to_postgres_etl.load_to_postgres manual__2025-10-27T15:03:52.290525+00:00 [running]> on host a0076f556b70
[2025-10-27T15:04:02.950+0000] {taskinstance.py:2648} INFO - Exporting env vars: AIRFLOW_CTX_DAG_OWNER='***' AIRFLOW_CTX_DAG_ID='mysql_to_postgres_etl' AIRFLOW_CTX_TASK_ID='load_to_postgres' AIRFLOW_CTX_EXECUTION_DATE='2025-10-27T15:03:52.290525+00:00' AIRFLOW_CTX_TRY_NUMBER='1' AIRFLOW_CTX_DAG_RUN_ID='manual__2025-10-27T15:03:52.290525+00:00'
[2025-10-27T15:04:02.951+0000] {taskinstance.py:430} INFO - ::endgroup::
[2025-10-27T15:04:03.891+0000] {base.py:84} INFO - Using connection ID 'postgres_con' for task execution.
[2025-10-27T15:04:03.901+0000] {base.py:84} INFO - Using connection ID 'postgres_con' for task execution.
[2025-10-27T15:04:03.903+0000] {mysql_to_postgres_etl.py:159} ERROR - Error in load_to_postgres: there is no unique or exclusion constraint matching the ON CONFLICT specification

[2025-10-27T15:04:03.904+0000] {taskinstance.py:441} INFO - ::group::Post task execution logs
[2025-10-27T15:04:03.905+0000] {taskinstance.py:2905} ERROR - Task failed with exception
Traceback (most recent call last):
  File "/home/airflow/.local/lib/python3.12/site-packages/airflow/models/taskinstance.py", line 465, in _execute_task
    result = _execute_callable(context=context, **execute_callable_kwargs)
             ^^^^^^^^^^^^^^^^^^^^^^^^^^^^^^^^^^^^^^^^^^^^^^^^^^^^^^^^^^^^^
  File "/home/airflow/.local/lib/python3.12/site-packages/airflow/models/taskinstance.py", line 432, in _execute_callable
    return execute_callable(context=context, **execute_callable_kwargs)
           ^^^^^^^^^^^^^^^^^^^^^^^^^^^^^^^^^^^^^^^^^^^^^^^^^^^^^^^^^^^^
  File "/home/airflow/.local/lib/python3.12/site-packages/airflow/models/baseoperator.py", line 401, in wrapper
    return func(self, *args, **kwargs)
           ^^^^^^^^^^^^^^^^^^^^^^^^^^^
  File "/home/airflow/.local/lib/python3.12/site-packages/airflow/operators/python.py", line 235, in execute
    return_value = self.execute_callable()
                   ^^^^^^^^^^^^^^^^^^^^^^^
  File "/home/airflow/.local/lib/python3.12/site-packages/airflow/operators/python.py", line 252, in execute_callable
    return self.python_callable(*self.op_args, **self.op_kwargs)
           ^^^^^^^^^^^^^^^^^^^^^^^^^^^^^^^^^^^^^^^^^^^^^^^^^^^^^
  File "/opt/airflow/dags/mysql_to_postgres_etl.py", line 145, in load_to_postgres
    pg_hook.insert_rows(
  File "/home/airflow/.local/lib/python3.12/site-packages/airflow/providers/common/sql/hooks/sql.py", line 606, in insert_rows
    cur.executemany(sql, values)
psycopg2.errors.InvalidColumnReference: there is no unique or exclusion constraint matching the ON CONFLICT specification

[2025-10-27T15:04:03.913+0000] {taskinstance.py:1206} INFO - Marking task as UP_FOR_RETRY. dag_id=mysql_to_postgres_etl, task_id=load_to_postgres, run_id=manual__2025-10-27T15:03:52.290525+00:00, execution_date=20251027T150352, start_date=20251027T150402, end_date=20251027T150403
[2025-10-27T15:04:03.925+0000] {standard_task_runner.py:110} ERROR - Failed to execute job 43 for task load_to_postgres (there is no unique or exclusion constraint matching the ON CONFLICT specification
; 746)
[2025-10-27T15:04:03.972+0000] {local_task_job_runner.py:243} INFO - Task exited with return code 1
[2025-10-27T15:04:03.990+0000] {taskinstance.py:3503} INFO - 0 downstream tasks scheduled from follow-on schedule check
[2025-10-27T15:04:03.991+0000] {local_task_job_runner.py:222} INFO - ::endgroup::
