[2025-10-27T15:05:32.879+0000] {local_task_job_runner.py:120} INFO - ::group::Pre task execution logs
[2025-10-27T15:05:32.901+0000] {taskinstance.py:2076} INFO - Dependencies all met for dep_context=non-requeueable deps ti=<TaskInstance: mysql_to_postgres_etl.load_to_postgres scheduled__2025-10-27T13:00:00+00:00 [queued]>
[2025-10-27T15:05:32.907+0000] {taskinstance.py:2076} INFO - Dependencies all met for dep_context=requeueable deps ti=<TaskInstance: mysql_to_postgres_etl.load_to_postgres scheduled__2025-10-27T13:00:00+00:00 [queued]>
[2025-10-27T15:05:32.908+0000] {taskinstance.py:2306} INFO - Starting attempt 2 of 2
[2025-10-27T15:05:32.922+0000] {taskinstance.py:2330} INFO - Executing <Task(PythonOperator): load_to_postgres> on 2025-10-27 13:00:00+00:00
[2025-10-27T15:05:32.930+0000] {warnings.py:112} WARNING - /home/***/.local/lib/python3.12/site-packages/***/task/task_runner/standard_task_runner.py:62: DeprecationWarning: This process (pid=795) is multi-threaded, use of fork() may lead to deadlocks in the child.
  pid = os.fork()

[2025-10-27T15:05:32.932+0000] {standard_task_runner.py:64} INFO - Started process 797 to run task
[2025-10-27T15:05:32.932+0000] {standard_task_runner.py:90} INFO - Running: ['***', 'tasks', 'run', 'mysql_to_postgres_etl', 'load_to_postgres', 'scheduled__2025-10-27T13:00:00+00:00', '--job-id', '45', '--raw', '--subdir', 'DAGS_FOLDER/mysql_to_postgres_etl.py', '--cfg-path', '/tmp/tmpcwqflk4v']
[2025-10-27T15:05:32.933+0000] {standard_task_runner.py:91} INFO - Job 45: Subtask load_to_postgres
[2025-10-27T15:05:32.976+0000] {task_command.py:426} INFO - Running <TaskInstance: mysql_to_postgres_etl.load_to_postgres scheduled__2025-10-27T13:00:00+00:00 [running]> on host a0076f556b70
[2025-10-27T15:05:33.368+0000] {taskinstance.py:2648} INFO - Exporting env vars: AIRFLOW_CTX_DAG_OWNER='***' AIRFLOW_CTX_DAG_ID='mysql_to_postgres_etl' AIRFLOW_CTX_TASK_ID='load_to_postgres' AIRFLOW_CTX_EXECUTION_DATE='2025-10-27T13:00:00+00:00' AIRFLOW_CTX_TRY_NUMBER='2' AIRFLOW_CTX_DAG_RUN_ID='scheduled__2025-10-27T13:00:00+00:00'
[2025-10-27T15:05:33.369+0000] {taskinstance.py:430} INFO - ::endgroup::
[2025-10-27T15:05:33.750+0000] {base.py:84} INFO - Using connection ID 'postgres_con' for task execution.
[2025-10-27T15:05:33.760+0000] {mysql_to_postgres_etl.py:177} ERROR - Error in load_to_postgres: there is no unique or exclusion constraint matching the ON CONFLICT specification

[2025-10-27T15:05:33.761+0000] {taskinstance.py:441} INFO - ::group::Post task execution logs
[2025-10-27T15:05:33.761+0000] {taskinstance.py:2905} ERROR - Task failed with exception
Traceback (most recent call last):
  File "/home/airflow/.local/lib/python3.12/site-packages/airflow/models/taskinstance.py", line 465, in _execute_task
    result = _execute_callable(context=context, **execute_callable_kwargs)
             ^^^^^^^^^^^^^^^^^^^^^^^^^^^^^^^^^^^^^^^^^^^^^^^^^^^^^^^^^^^^^
  File "/home/airflow/.local/lib/python3.12/site-packages/airflow/models/taskinstance.py", line 432, in _execute_callable
    return execute_callable(context=context, **execute_callable_kwargs)
           ^^^^^^^^^^^^^^^^^^^^^^^^^^^^^^^^^^^^^^^^^^^^^^^^^^^^^^^^^^^^
  File "/home/airflow/.local/lib/python3.12/site-packages/airflow/models/baseoperator.py", line 401, in wrapper
    return func(self, *args, **kwargs)
           ^^^^^^^^^^^^^^^^^^^^^^^^^^^
  File "/home/airflow/.local/lib/python3.12/site-packages/airflow/operators/python.py", line 235, in execute
    return_value = self.execute_callable()
                   ^^^^^^^^^^^^^^^^^^^^^^^
  File "/home/airflow/.local/lib/python3.12/site-packages/airflow/operators/python.py", line 252, in execute_callable
    return self.python_callable(*self.op_args, **self.op_kwargs)
           ^^^^^^^^^^^^^^^^^^^^^^^^^^^^^^^^^^^^^^^^^^^^^^^^^^^^^
  File "/opt/airflow/dags/mysql_to_postgres_etl.py", line 171, in load_to_postgres
    execute_values(cur, insert_sql, records)
  File "/home/airflow/.local/lib/python3.12/site-packages/psycopg2/extras.py", line 1299, in execute_values
    cur.execute(b''.join(parts))
psycopg2.errors.InvalidColumnReference: there is no unique or exclusion constraint matching the ON CONFLICT specification

[2025-10-27T15:05:33.770+0000] {taskinstance.py:1206} INFO - Marking task as FAILED. dag_id=mysql_to_postgres_etl, task_id=load_to_postgres, run_id=scheduled__2025-10-27T13:00:00+00:00, execution_date=20251027T130000, start_date=20251027T150532, end_date=20251027T150533
[2025-10-27T15:05:33.783+0000] {standard_task_runner.py:110} ERROR - Failed to execute job 45 for task load_to_postgres (there is no unique or exclusion constraint matching the ON CONFLICT specification
; 797)
[2025-10-27T15:05:33.809+0000] {local_task_job_runner.py:243} INFO - Task exited with return code 1
[2025-10-27T15:05:33.826+0000] {taskinstance.py:3503} INFO - 0 downstream tasks scheduled from follow-on schedule check
[2025-10-27T15:05:33.829+0000] {local_task_job_runner.py:222} INFO - ::endgroup::
