[2025-10-27T14:55:43.761+0000] {local_task_job_runner.py:120} INFO - ::group::Pre task execution logs
[2025-10-27T14:55:43.781+0000] {taskinstance.py:2076} INFO - Dependencies all met for dep_context=non-requeueable deps ti=<TaskInstance: mysql_to_postgres_etl.test_connections manual__2025-10-27T14:55:42.239718+00:00 [queued]>
[2025-10-27T14:55:43.786+0000] {taskinstance.py:2076} INFO - Dependencies all met for dep_context=requeueable deps ti=<TaskInstance: mysql_to_postgres_etl.test_connections manual__2025-10-27T14:55:42.239718+00:00 [queued]>
[2025-10-27T14:55:43.786+0000] {taskinstance.py:2306} INFO - Starting attempt 1 of 2
[2025-10-27T14:55:43.796+0000] {taskinstance.py:2330} INFO - Executing <Task(PythonOperator): test_connections> on 2025-10-27 14:55:42.239718+00:00
[2025-10-27T14:55:43.802+0000] {warnings.py:112} WARNING - /home/***/.local/lib/python3.12/site-packages/***/task/task_runner/standard_task_runner.py:62: DeprecationWarning: This process (pid=360) is multi-threaded, use of fork() may lead to deadlocks in the child.
  pid = os.fork()

[2025-10-27T14:55:43.803+0000] {standard_task_runner.py:64} INFO - Started process 362 to run task
[2025-10-27T14:55:43.804+0000] {standard_task_runner.py:90} INFO - Running: ['***', 'tasks', 'run', 'mysql_to_postgres_etl', 'test_connections', 'manual__2025-10-27T14:55:42.239718+00:00', '--job-id', '12', '--raw', '--subdir', 'DAGS_FOLDER/mysql_to_postgres_etl.py', '--cfg-path', '/tmp/tmp_lblcqea']
[2025-10-27T14:55:43.805+0000] {standard_task_runner.py:91} INFO - Job 12: Subtask test_connections
[2025-10-27T14:55:43.838+0000] {task_command.py:426} INFO - Running <TaskInstance: mysql_to_postgres_etl.test_connections manual__2025-10-27T14:55:42.239718+00:00 [running]> on host a0076f556b70
[2025-10-27T14:55:43.904+0000] {taskinstance.py:2648} INFO - Exporting env vars: AIRFLOW_CTX_DAG_OWNER='***' AIRFLOW_CTX_DAG_ID='mysql_to_postgres_etl' AIRFLOW_CTX_TASK_ID='test_connections' AIRFLOW_CTX_EXECUTION_DATE='2025-10-27T14:55:42.239718+00:00' AIRFLOW_CTX_TRY_NUMBER='1' AIRFLOW_CTX_DAG_RUN_ID='manual__2025-10-27T14:55:42.239718+00:00'
[2025-10-27T14:55:43.905+0000] {taskinstance.py:430} INFO - ::endgroup::
[2025-10-27T14:55:43.912+0000] {mysql_to_postgres_etl.py:33} ERROR - Connection test failed: The conn_id `mysql_default` isn't defined
[2025-10-27T14:55:43.912+0000] {taskinstance.py:441} INFO - ::group::Post task execution logs
[2025-10-27T14:55:43.920+0000] {taskinstance.py:2905} ERROR - Task failed with exception
Traceback (most recent call last):
  File "/home/airflow/.local/lib/python3.12/site-packages/airflow/models/taskinstance.py", line 465, in _execute_task
    result = _execute_callable(context=context, **execute_callable_kwargs)
             ^^^^^^^^^^^^^^^^^^^^^^^^^^^^^^^^^^^^^^^^^^^^^^^^^^^^^^^^^^^^^
  File "/home/airflow/.local/lib/python3.12/site-packages/airflow/models/taskinstance.py", line 432, in _execute_callable
    return execute_callable(context=context, **execute_callable_kwargs)
           ^^^^^^^^^^^^^^^^^^^^^^^^^^^^^^^^^^^^^^^^^^^^^^^^^^^^^^^^^^^^
  File "/home/airflow/.local/lib/python3.12/site-packages/airflow/models/baseoperator.py", line 401, in wrapper
    return func(self, *args, **kwargs)
           ^^^^^^^^^^^^^^^^^^^^^^^^^^^
  File "/home/airflow/.local/lib/python3.12/site-packages/airflow/operators/python.py", line 235, in execute
    return_value = self.execute_callable()
                   ^^^^^^^^^^^^^^^^^^^^^^^
  File "/home/airflow/.local/lib/python3.12/site-packages/airflow/operators/python.py", line 252, in execute_callable
    return self.python_callable(*self.op_args, **self.op_kwargs)
           ^^^^^^^^^^^^^^^^^^^^^^^^^^^^^^^^^^^^^^^^^^^^^^^^^^^^^
  File "/opt/airflow/dags/mysql_to_postgres_etl.py", line 17, in test_connections
    mysql_conn = mysql_hook.get_conn()
                 ^^^^^^^^^^^^^^^^^^^^^
  File "/home/airflow/.local/lib/python3.12/site-packages/airflow/providers/mysql/hooks/mysql.py", line 188, in get_conn
    conn = self.connection or self.get_connection(getattr(self, self.conn_name_attr))
                              ^^^^^^^^^^^^^^^^^^^^^^^^^^^^^^^^^^^^^^^^^^^^^^^^^^^^^^^
  File "/home/airflow/.local/lib/python3.12/site-packages/airflow/hooks/base.py", line 83, in get_connection
    conn = Connection.get_connection_from_secrets(conn_id)
           ^^^^^^^^^^^^^^^^^^^^^^^^^^^^^^^^^^^^^^^^^^^^^^^
  File "/home/airflow/.local/lib/python3.12/site-packages/airflow/models/connection.py", line 519, in get_connection_from_secrets
    raise AirflowNotFoundException(f"The conn_id `{conn_id}` isn't defined")
airflow.exceptions.AirflowNotFoundException: The conn_id `mysql_default` isn't defined
[2025-10-27T14:55:43.924+0000] {taskinstance.py:1206} INFO - Marking task as UP_FOR_RETRY. dag_id=mysql_to_postgres_etl, task_id=test_connections, run_id=manual__2025-10-27T14:55:42.239718+00:00, execution_date=20251027T145542, start_date=20251027T145543, end_date=20251027T145543
[2025-10-27T14:55:43.934+0000] {standard_task_runner.py:110} ERROR - Failed to execute job 12 for task test_connections (The conn_id `mysql_default` isn't defined; 362)
[2025-10-27T14:55:43.985+0000] {local_task_job_runner.py:243} INFO - Task exited with return code 1
[2025-10-27T14:55:43.997+0000] {local_task_job_runner.py:222} INFO - ::endgroup::
